2023-11-21 21:48:30,015 - ERROR - Exception on /drones [GET]
Traceback (most recent call last):
  File "C:\Users\Auri\AppData\Local\Programs\Python\Python310\lib\site-packages\sqlalchemy\engine\base.py", line 1969, in _exec_single_context
    self.dialect.do_execute(
  File "C:\Users\Auri\AppData\Local\Programs\Python\Python310\lib\site-packages\sqlalchemy\engine\default.py", line 922, in do_execute
    cursor.execute(statement, parameters)
sqlite3.OperationalError: no such table: drone

The above exception was the direct cause of the following exception:

Traceback (most recent call last):
  File "C:\Users\Auri\AppData\Local\Programs\Python\Python310\lib\site-packages\flask\app.py", line 867, in full_dispatch_request
    rv = self.dispatch_request()
  File "C:\Users\Auri\AppData\Local\Programs\Python\Python310\lib\site-packages\flask\app.py", line 852, in dispatch_request
    return self.ensure_sync(self.view_functions[rule.endpoint])(**view_args)
  File "C:\Users\Auri\AppData\Local\Programs\Python\Python310\lib\site-packages\flask_restful\__init__.py", line 489, in wrapper
    resp = resource(*args, **kwargs)
  File "C:\Users\Auri\AppData\Local\Programs\Python\Python310\lib\site-packages\flask\views.py", line 109, in view
    return current_app.ensure_sync(self.dispatch_request)(**kwargs)
  File "C:\Users\Auri\AppData\Local\Programs\Python\Python310\lib\site-packages\flask_restful\__init__.py", line 604, in dispatch_request
    resp = meth(*args, **kwargs)
  File "C:\Users\Auri\AppData\Local\Programs\Python\Python310\lib\site-packages\Drone_Management_API\Drone_Management_API.py", line 132, in get
    drones = Drone.query.all()
  File "C:\Users\Auri\AppData\Local\Programs\Python\Python310\lib\site-packages\sqlalchemy\orm\query.py", line 2693, in all
    return self._iter().all()  # type: ignore
  File "C:\Users\Auri\AppData\Local\Programs\Python\Python310\lib\site-packages\sqlalchemy\orm\query.py", line 2847, in _iter
    result: Union[ScalarResult[_T], Result[_T]] = self.session.execute(
  File "C:\Users\Auri\AppData\Local\Programs\Python\Python310\lib\site-packages\sqlalchemy\orm\session.py", line 2308, in execute
    return self._execute_internal(
  File "C:\Users\Auri\AppData\Local\Programs\Python\Python310\lib\site-packages\sqlalchemy\orm\session.py", line 2190, in _execute_internal
    result: Result[Any] = compile_state_cls.orm_execute_statement(
  File "C:\Users\Auri\AppData\Local\Programs\Python\Python310\lib\site-packages\sqlalchemy\orm\context.py", line 293, in orm_execute_statement
    result = conn.execute(
  File "C:\Users\Auri\AppData\Local\Programs\Python\Python310\lib\site-packages\sqlalchemy\engine\base.py", line 1416, in execute
    return meth(
  File "C:\Users\Auri\AppData\Local\Programs\Python\Python310\lib\site-packages\sqlalchemy\sql\elements.py", line 516, in _execute_on_connection
    return connection._execute_clauseelement(
  File "C:\Users\Auri\AppData\Local\Programs\Python\Python310\lib\site-packages\sqlalchemy\engine\base.py", line 1639, in _execute_clauseelement
    ret = self._execute_context(
  File "C:\Users\Auri\AppData\Local\Programs\Python\Python310\lib\site-packages\sqlalchemy\engine\base.py", line 1848, in _execute_context
    return self._exec_single_context(
  File "C:\Users\Auri\AppData\Local\Programs\Python\Python310\lib\site-packages\sqlalchemy\engine\base.py", line 1988, in _exec_single_context
    self._handle_dbapi_exception(
  File "C:\Users\Auri\AppData\Local\Programs\Python\Python310\lib\site-packages\sqlalchemy\engine\base.py", line 2343, in _handle_dbapi_exception
    raise sqlalchemy_exception.with_traceback(exc_info[2]) from e
  File "C:\Users\Auri\AppData\Local\Programs\Python\Python310\lib\site-packages\sqlalchemy\engine\base.py", line 1969, in _exec_single_context
    self.dialect.do_execute(
  File "C:\Users\Auri\AppData\Local\Programs\Python\Python310\lib\site-packages\sqlalchemy\engine\default.py", line 922, in do_execute
    cursor.execute(statement, parameters)
sqlalchemy.exc.OperationalError: (sqlite3.OperationalError) no such table: drone
[SQL: SELECT drone.id AS drone_id, drone.serial_number AS drone_serial_number, drone.model AS drone_model, drone.weight_limit AS drone_weight_limit, drone.battery_capacity AS drone_battery_capacity, drone.state AS drone_state 
FROM drone]
(Background on this error at: https://sqlalche.me/e/20/e3q8)
2023-11-21 21:48:56,702 - ERROR - Exception on /drones [GET]
Traceback (most recent call last):
  File "C:\Users\Auri\AppData\Local\Programs\Python\Python310\lib\site-packages\sqlalchemy\engine\base.py", line 1969, in _exec_single_context
    self.dialect.do_execute(
  File "C:\Users\Auri\AppData\Local\Programs\Python\Python310\lib\site-packages\sqlalchemy\engine\default.py", line 922, in do_execute
    cursor.execute(statement, parameters)
sqlite3.OperationalError: no such table: drone

The above exception was the direct cause of the following exception:

Traceback (most recent call last):
  File "C:\Users\Auri\AppData\Local\Programs\Python\Python310\lib\site-packages\flask\app.py", line 867, in full_dispatch_request
    rv = self.dispatch_request()
  File "C:\Users\Auri\AppData\Local\Programs\Python\Python310\lib\site-packages\flask\app.py", line 852, in dispatch_request
    return self.ensure_sync(self.view_functions[rule.endpoint])(**view_args)
  File "C:\Users\Auri\AppData\Local\Programs\Python\Python310\lib\site-packages\flask_restful\__init__.py", line 489, in wrapper
    resp = resource(*args, **kwargs)
  File "C:\Users\Auri\AppData\Local\Programs\Python\Python310\lib\site-packages\flask\views.py", line 109, in view
    return current_app.ensure_sync(self.dispatch_request)(**kwargs)
  File "C:\Users\Auri\AppData\Local\Programs\Python\Python310\lib\site-packages\flask_restful\__init__.py", line 604, in dispatch_request
    resp = meth(*args, **kwargs)
  File "C:\Users\Auri\AppData\Local\Programs\Python\Python310\lib\site-packages\Drone_Management_API\Drone_Management_API.py", line 132, in get
    drones = Drone.query.all()
  File "C:\Users\Auri\AppData\Local\Programs\Python\Python310\lib\site-packages\sqlalchemy\orm\query.py", line 2693, in all
    return self._iter().all()  # type: ignore
  File "C:\Users\Auri\AppData\Local\Programs\Python\Python310\lib\site-packages\sqlalchemy\orm\query.py", line 2847, in _iter
    result: Union[ScalarResult[_T], Result[_T]] = self.session.execute(
  File "C:\Users\Auri\AppData\Local\Programs\Python\Python310\lib\site-packages\sqlalchemy\orm\session.py", line 2308, in execute
    return self._execute_internal(
  File "C:\Users\Auri\AppData\Local\Programs\Python\Python310\lib\site-packages\sqlalchemy\orm\session.py", line 2190, in _execute_internal
    result: Result[Any] = compile_state_cls.orm_execute_statement(
  File "C:\Users\Auri\AppData\Local\Programs\Python\Python310\lib\site-packages\sqlalchemy\orm\context.py", line 293, in orm_execute_statement
    result = conn.execute(
  File "C:\Users\Auri\AppData\Local\Programs\Python\Python310\lib\site-packages\sqlalchemy\engine\base.py", line 1416, in execute
    return meth(
  File "C:\Users\Auri\AppData\Local\Programs\Python\Python310\lib\site-packages\sqlalchemy\sql\elements.py", line 516, in _execute_on_connection
    return connection._execute_clauseelement(
  File "C:\Users\Auri\AppData\Local\Programs\Python\Python310\lib\site-packages\sqlalchemy\engine\base.py", line 1639, in _execute_clauseelement
    ret = self._execute_context(
  File "C:\Users\Auri\AppData\Local\Programs\Python\Python310\lib\site-packages\sqlalchemy\engine\base.py", line 1848, in _execute_context
    return self._exec_single_context(
  File "C:\Users\Auri\AppData\Local\Programs\Python\Python310\lib\site-packages\sqlalchemy\engine\base.py", line 1988, in _exec_single_context
    self._handle_dbapi_exception(
  File "C:\Users\Auri\AppData\Local\Programs\Python\Python310\lib\site-packages\sqlalchemy\engine\base.py", line 2343, in _handle_dbapi_exception
    raise sqlalchemy_exception.with_traceback(exc_info[2]) from e
  File "C:\Users\Auri\AppData\Local\Programs\Python\Python310\lib\site-packages\sqlalchemy\engine\base.py", line 1969, in _exec_single_context
    self.dialect.do_execute(
  File "C:\Users\Auri\AppData\Local\Programs\Python\Python310\lib\site-packages\sqlalchemy\engine\default.py", line 922, in do_execute
    cursor.execute(statement, parameters)
sqlalchemy.exc.OperationalError: (sqlite3.OperationalError) no such table: drone
[SQL: SELECT drone.id AS drone_id, drone.serial_number AS drone_serial_number, drone.model AS drone_model, drone.weight_limit AS drone_weight_limit, drone.battery_capacity AS drone_battery_capacity, drone.state AS drone_state 
FROM drone]
(Background on this error at: https://sqlalche.me/e/20/e3q8)
